<?xml version="1.0" ?>
<!-- =================================================================================== -->
<!-- |    This document was autogenerated by xacro from ./ur_description/urdf/ur5_robot.urdf.xacro | -->
<!-- |    EDITING THIS FILE BY HAND IS NOT RECOMMENDED                                 | -->
<!-- =================================================================================== -->
<robot name="ur5" xmlns:xacro="http://ros.org/wiki/xacro">
  <link name="base_link">
  </link>
  <joint name="left_gripper" type="prismatic">
    <parent link="base_link"/>
    <child link="left_gripper_link"/>
    <origin rpy="0 0 0" xyz="0.06 -0.005 0"/>
    <limit effort="100" lower="0.0" upper="0.1" velocity="0.01"/>
    <axis xyz="-1 0 0"/>
  </joint>
  <joint name="right_gripper" type="prismatic">
    <parent link="base_link"/>
    <child link="right_gripper_link"/>
    <origin rpy="0 0 0" xyz="-0.06 0.005 0"/>
    <limit effort="100" lower="0" upper="0.1" velocity="0.01"/>
  </joint>
  <link name="left_gripper_link">
    <visual>
      <origin rpy="0 1.57079632679 3.141593" xyz="0 0 0"/>
      <geometry>
        <mesh filename="meshes/finger.stl"/>
      </geometry>
    </visual>
    <collision>
      <origin rpy="0 1.57079632679 3.141593 " xyz="0 0 0"/>
      <geometry>
        <mesh filename="meshes/finger.stl"/>
      </geometry>
    </collision>
    <inertial>
      <mass value="3.7"/>
      <origin rpy="0 0 0" xyz="0.0 0.0 0.0"/>
    </inertial>
  </link>
  <link name="right_gripper_link">
    <visual>
      <origin rpy="0 1.57079632679 0" xyz="0 0 0"/>
      <geometry>
        <mesh filename="meshes/finger.stl"/>
      </geometry>
    </visual>
    <collision>
      <origin rpy="0 1.57079632679 0" xyz="0 0 0"/>
      <geometry>
        <mesh filename="meshes/finger.stl"/>
      </geometry>
    </collision>
    <inertial>
      <mass value="3.7"/>
      <origin rpy="0 0 0" xyz="0.0 0.0 0.0"/>
    </inertial>
  </link>
  <link name="world"/>
  <joint name="world_joint" type="floating">
    <parent link="world"/>
    <child link="base_link"/>
    <origin rpy="0.0 0.0 0.0" xyz="0.0 0.0 0.0"/>
  </joint>
</robot>

